Traceback (most recent call last):
  File "extra.py", line 2, in <module>
    import tensorflow as tf
  File "/home/apps/TENSORFLOW_GPU/1.5.0/gpu/lib/python2.7/site-packages/tensorflow/__init__.py", line 24, in <module>
    from tensorflow.python import *
  File "/home/apps/TENSORFLOW_GPU/1.5.0/gpu/lib/python2.7/site-packages/tensorflow/python/__init__.py", line 52, in <module>
    from tensorflow.core.framework.graph_pb2 import *
  File "/home/apps/TENSORFLOW_GPU/1.5.0/gpu/lib/python2.7/site-packages/tensorflow/core/framework/graph_pb2.py", line 6, in <module>
    from google.protobuf import descriptor as _descriptor
  File "/home/apps/PYTHONPACKAGES/2.7.13/protobuf/3.5.0/gnu/lib/python2.7/site-packages/google/protobuf/__init__.py", line 37, in <module>
    __import__('pkg_resources').declare_namespace(__name__)
  File "/home/apps/PYTHONPACKAGES/2.7.13/ucs4/gnu/447/DISTRIBUTE/0.6.28/gnu/lib/python2.7/site-packages/distribute-0.6.28-py2.7.egg/pkg_resources.py", line 2835, in <module>
    add_activation_listener(lambda dist: dist.activate())
  File "/home/apps/PYTHONPACKAGES/2.7.13/ucs4/gnu/447/DISTRIBUTE/0.6.28/gnu/lib/python2.7/site-packages/distribute-0.6.28-py2.7.egg/pkg_resources.py", line 704, in subscribe
    callback(dist)
  File "/home/apps/PYTHONPACKAGES/2.7.13/ucs4/gnu/447/DISTRIBUTE/0.6.28/gnu/lib/python2.7/site-packages/distribute-0.6.28-py2.7.egg/pkg_resources.py", line 2835, in <lambda>
    add_activation_listener(lambda dist: dist.activate())
  File "/home/apps/PYTHONPACKAGES/2.7.13/ucs4/gnu/447/DISTRIBUTE/0.6.28/gnu/lib/python2.7/site-packages/distribute-0.6.28-py2.7.egg/pkg_resources.py", line 2259, in activate
    self.insert_on(path)
  File "/home/apps/PYTHONPACKAGES/2.7.13/ucs4/gnu/447/DISTRIBUTE/0.6.28/gnu/lib/python2.7/site-packages/distribute-0.6.28-py2.7.egg/pkg_resources.py", line 2366, in insert_on
    self.check_version_conflict()
  File "/home/apps/PYTHONPACKAGES/2.7.13/ucs4/gnu/447/DISTRIBUTE/0.6.28/gnu/lib/python2.7/site-packages/distribute-0.6.28-py2.7.egg/pkg_resources.py", line 2405, in check_version_conflict
    for modname in self._get_metadata('top_level.txt'):
  File "/home/apps/PYTHONPACKAGES/2.7.13/ucs4/gnu/447/DISTRIBUTE/0.6.28/gnu/lib/python2.7/site-packages/distribute-0.6.28-py2.7.egg/pkg_resources.py", line 2253, in _get_metadata
    for line in self.get_metadata_lines(name):
  File "/home/apps/PYTHONPACKAGES/2.7.13/ucs4/gnu/447/DISTRIBUTE/0.6.28/gnu/lib/python2.7/site-packages/distribute-0.6.28-py2.7.egg/pkg_resources.py", line 1213, in get_metadata_lines
    return yield_lines(self.get_metadata(name))
  File "/home/apps/PYTHONPACKAGES/2.7.13/ucs4/gnu/447/DISTRIBUTE/0.6.28/gnu/lib/python2.7/site-packages/distribute-0.6.28-py2.7.egg/pkg_resources.py", line 1205, in get_metadata
    return self._get(self._fn(self.egg_info,name))
  File "/home/apps/PYTHONPACKAGES/2.7.13/ucs4/gnu/447/DISTRIBUTE/0.6.28/gnu/lib/python2.7/site-packages/distribute-0.6.28-py2.7.egg/pkg_resources.py", line 1320, in _get
    stream = open(path, 'rb')
IOError: [Errno 13] Permission denied: '/home/apps/PYTHONPACKAGES/2.7.13/absl-py/0.1.10/gnu/lib/python2.7/site-packages/absl_py-0.1.10-py2.7.egg/EGG-INFO/top_level.txt'

